<!-- The Lappa robot -->
<mujoco model="Lappa">
	<worldbody>
		<body name="root" pos="0 0 0">
			<joint name="root_a" type="free" stiffness="0.015" />
			<geom name="core" type="cylinder" fromto="-.05 0 -.01 .05 0 -.01" size=".015" mass=".001" />
            <body name="a_module" pos="-.2 0 0">
                <geom name="a_house" type="cylinder" fromto="0 0 -.025 0 0 0" size=".15" rgba="1 0 0 1" mass=".002" />
                <joint type="hinge" name="a_h2" axis="0 1 0" pos=".15 0 0" limited="true" range="-90 90" stiffness=".0025" />
                <joint type="hinge" name="a_h3" axis="1 0 0" pos=".2 0 0" limited="true" range="-90 90" stiffness=".05" />
                <body name="a_chamber">
                    <joint type="hinge" name="a_h1" axis="0 0 1" limited="true" range="-180 180" />
                    <geom name="test" pos="0 0 .025" type="box" size=".02 .02 0.005" rgba="1 0 0 1" mass="0" />
                    <geom name="a_chamber1" type="cylinder" fromto="0 0 .01 0 0 -.051" size=".083" rgba="0 0 1 1" mass=".002" />
                    <geom name="a_chamber2" type="cylinder" fromto="0 0 -.05 0 0 -.1" size=".12" rgba="0 0 1 1" mass=".075" />
                    <site name="a_propeller" pos="0 0 -.05" />
                </body>
            </body>
            <body name="b_module" pos=".2 0 0">
                <geom name="b_housing" type="cylinder" fromto="0 0 -.025 0 0 0" size=".15" rgba="1 .4 .7 1" mass=".002" />
                <joint type="hinge" name="b_h2" axis="0 1 0" pos="-.15 0 0" limited="true" range="-90 90" stiffness=".0025" />
                <joint type="hinge" name="b_h3" axis="1 0 0" pos="-.25 0 0" limited="true" range="-90 90" stiffness=".075" />
                <body name="b_chamber">
                    <joint type="hinge" name="b_h1" axis="0 0 1" limited="true" range="-180 180" />
                    <geom name="test2" pos="0 0 .025" type="box" size=".02 .02 0.005" rgba="1 0 0 1" mass="0" />
                    <geom name="b_chamber1" type="cylinder" fromto="0 0 .01 0 0 -.051" size=".083" rgba="0 1 1 1" mass=".002" />
                    <geom name="b_chamber2" type="cylinder" fromto="0 0 -.05 0 0 -.1" size=".12" rgba="0 1 1 1" mass=".075" />
                    <site name="b_propeller" pos="0 0 -.05" />
                </body>
            </body>
		</body>
	</worldbody>
	<equality>
        <joint joint1="a_h1" joint2="b_h1" />
	</equality>
	<actuator>
        <motor name="a_thrust" site="a_propeller" ctrllimited="true" ctrlrange="-1. 1." gear="0 0 10"  />
        <motor name="b_thrust" site="b_propeller" ctrllimited="true" ctrlrange="-1. 1." gear="0 0 10"  />
        <motor name="a_rotor" joint="a_h1" gear=".5"  />
	</actuator>
</mujoco>