<mujoco>

<worldbody>
    <!-- Define the body for the first module -->
		<body name="module1_body" pos="0 0 2">
            <joint name="module1_joint" type="free" />
			<geom name="module1_geom" type="box" size="0.1 0.2 0.05" rgba="0.5 0.5 0.5 1" />
		</body>
		<!-- Define the body for the second module -->
		<body name="module2_body" pos="1 0 2">
            <joint name="module2_joint" type="free" />
			<geom name="module2_geom" type="box" size="0.1 0.2 0.05" rgba="0.5 0.5 0.5 1" />
		</body>
		<!-- Define the arm connecting the two modules -->
		<body name="arm_body" pos=".5 0 2">
			<joint name="arm_joint" type="hinge" pos="0 0 0.1" axis="1 0 0" />
			<geom name="arm_geom" type="capsule" size="0.05 0.2" rgba="0.5 0.5 0.5 1" euler="0 90 0" />
		</body>
</worldbody>
</mujoco>