<!-- The Lappa robot -->
<mujoco model="Lappa">
	<worldbody>
		<body name="root">
			<geom name="core" type="cylinder" fromto="-.1 0 0 .1 0 0" size=".005" mass=".0001" />
			<body name="torsion_bar">
				<geom name="spring" type="cylinder" size="0.02 .195" euler="0 90 0" rgba="1 1 0 1" mass="0.01" />
				<joint name="h3" type="hinge" axis="1 0 0" limited="true" range="-90 90" stiffness="5" damping="10" />
			</body>
			<freejoint name="root_joint" />
			<body name="a_module" pos=".4 0 0">
				<geom name="a_house" type="cylinder" size=".195 .005" rgba="1 0 0 1" mass="0.2" />
				<geom name="a_lock" type="box" size=".113 .113 .005" pos="0 0 .005" mass="0" />
				<joint name="a_h2" type="hinge" axis="0 1 0" pos="-.195 0 0" limited="true" range="-45 45" />
				<body name="a_chamber" pos="0 0 -.1">
					<joint name="a_h1" type="hinge" axis="0 0 1" />
					<geom name="a_chamber" type="cylinder" size=".110 .100" rgba="0 0 1 1" mass="0.45" />
                    <site name="a_propeller" pos="0 0 -.05" />
				</body>
			</body>
			<body name="b_module" pos="-.4 0 0">
				<geom name="b_house" type="cylinder" size=".195 .005" rgba="1 0 0 1" mass="0.2" />
				<geom name="b_lock" type="box" size=".113 .113 .005" pos="0 0 .005" mass="0" />
				<joint name="b_h2" type="hinge" axis="0 1 0" pos=".195 0 0" limited="true" range="-45 45" />
				<body name="b_chamber" pos="0 0 -.1">
					<joint name="b_h1" type="hinge" axis="0 0 1" />
					<geom name="b_chamber" type="cylinder" size=".110 .100" rgba="0 0 1 1" mass="0.45" />
                    <site name="b_propeller" pos="0 0 -.05" />
				</body>
			</body>
		</body>
	</worldbody>
	<equality>

	</equality>
	<actuator>
        <motor name="a_thrust" site="a_propeller" ctrllimited="true" ctrlrange="-1. 1." gear="0 0 100"  />
        <motor name="b_thrust" site="b_propeller" ctrllimited="true" ctrlrange="-1. 1." gear="0 0 100"  />
		<motor name="h3" joint="h3" gear="10" />
        <motor name="a_h1" joint="a_h1" gear="1" />
        <motor name="b_h1" joint="b_h1" gear="1" />
	</actuator>
</mujoco>
