<mujoco>
	<worldbody>
		<body name="root">
			<joint type="free" />
			<geom name="wires" type="box" pos="0 0 .005" size=".01 .01 .005" rgba="1 1 1 1" mass=".01" />
			<body name="a_module" pos="-.155 0 0">
				<geom name="a_house" type="cylinder" pos="0 0 0" size="0.0775 .0025" rgba=".2 .2 1 .35" mass=".15" />
				<joint name="a_h1" type="hinge" axis="0 0 1" limited="true" range="-180 180" stiffness="1" />
                <joint name="a_h2" type="hinge" pos=".0775 0 0" axis="0 1 0" limited="true" range="-45 45" />
				<geom name="a_connector" type="box" pos=".0775 0 0" size=".0125 .025 .0125" rgba="0 1 0 1" mass=".025" />
				<geom name="a_connector_part_a" type="box" pos="-.075 0 -.01" size=".005 .0125 .005" rgba="0 1 0 1" mass=".00000025" />
				<geom name="a_connector_part_b" type="box" pos="0 .075 -.01" size=".0125 .005 .005" rgba="0 1 0 1" mass=".00000025" />
				<geom name="a_connector_part_c" type="box" pos="0 -.075 -.01" size=".0125 .005 .005" rgba="0 1 0 1" mass=".00000025" />
				<body name="a_chamber" pos="0 0 0">
					<geom name="a_gear" type="cylinder" fromto="0 0 0 0 0 -.05" size=".044" rgba=".3 .3 .3 1" mass=".05" />
					<geom name="a_chamber" type="cylinder" fromto="0 0 -.05 0 0 -.1" size=".055" rgba="1 0 0 1" mass=".3" />
				</body>
			</body>
            <body name="connector">
                <joint name="h3" type="hinge" axis="1 0 0" limited="true" range="-90 90" stiffness="1" />
                <geom name="arm" type="cylinder" fromto="-.05 0 0 .05 0 0" size=".01" rgba="1 1 0 1" mass=".15" />
            </body>
            <body name="b_module" pos=".155 0 0" euler="0 0 180">
                <geom name="b_house" type="cylinder" pos="0 0 0" size="0.0775 .0025" rgba=".2 .2 1 .35" mass=".15" />
                <joint name="b_h1" type="hinge" axis="0 0 1" limited="true" range="-180 180" stiffness="1" />
                <joint name="b_h2" type="hinge" pos=".0775 0 0" axis="0 1 0" limited="true" range="-45 45" />
                <geom name="b_connector" type="box" pos=".0775 0 0" size=".0125 .025 .0125" rgba="0 1 0 1" mass=".025" />
                <geom name="b_connector_part_a" type="box" pos="-.075 0 -.01" size=".005 .0125 .005" rgba="0 1 0 1" mass=".00000025" />
                <geom name="b_connector_part_b" type="box" pos="0 .075 -.01" size=".0125 .005 .005" rgba="0 1 0 1" mass=".00000025" />
                <geom name="b_connector_part_c" type="box" pos="0 -.075 -.01" size=".0125 .005 .005" rgba="0 1 0 1" mass=".00000025" />
                <body name="b_chamber" pos="0 0 0">
                    <geom name="b_gear" type="cylinder" fromto="0 0 0 0 0 -.05" size=".044" rgba=".3 .3 .3 1" mass=".05" />
                    <geom name="b_chamber" type="cylinder" fromto="0 0 -.05 0 0 -.1" size=".055" rgba="1 0 0 1" mass=".3" />
                </body>
            </body>
		</body>
	</worldbody>
    <equality>
        <connect body1="a_module" body2="connector" anchor=".0775 0 0" />
        <connect body1="b_module" body2="connector" anchor=".0775 0 0" />
    </equality>
    <actuator>
        <motor name="a_h1" ctrllimited="true" ctrlrange="-1 1" joint="a_h1" gear="10" />
        <motor name="b_h1" ctrllimited="true" ctrlrange="-1 1" joint="b_h1" gear="10" />
    </actuator>
</mujoco>
